[2025-10-06T23:45:51.915+0000] {taskinstance.py:1083} INFO - Dependencies all met for <TaskInstance: pytorch_circle_classifier.wait_for_test_file scheduled__2025-10-05T00:00:00+00:00 [queued]>
[2025-10-06T23:45:51.920+0000] {taskinstance.py:1083} INFO - Dependencies all met for <TaskInstance: pytorch_circle_classifier.wait_for_test_file scheduled__2025-10-05T00:00:00+00:00 [queued]>
[2025-10-06T23:45:51.920+0000] {taskinstance.py:1279} INFO - 
--------------------------------------------------------------------------------
[2025-10-06T23:45:51.921+0000] {taskinstance.py:1280} INFO - Starting attempt 1 of 2
[2025-10-06T23:45:51.921+0000] {taskinstance.py:1281} INFO - 
--------------------------------------------------------------------------------
[2025-10-06T23:45:51.929+0000] {taskinstance.py:1300} INFO - Executing <Task(FileSensor): wait_for_test_file> on 2025-10-05 00:00:00+00:00
[2025-10-06T23:45:51.939+0000] {standard_task_runner.py:55} INFO - Started process 130 to run task
[2025-10-06T23:45:51.942+0000] {standard_task_runner.py:82} INFO - Running: ['***', 'tasks', 'run', 'pytorch_circle_classifier', 'wait_for_test_file', 'scheduled__2025-10-05T00:00:00+00:00', '--job-id', '8', '--raw', '--subdir', 'DAGS_FOLDER/***.py', '--cfg-path', '/tmp/tmp_rorz2qk']
[2025-10-06T23:45:51.945+0000] {standard_task_runner.py:83} INFO - Job 8: Subtask wait_for_test_file
[2025-10-06T23:45:51.999+0000] {task_command.py:388} INFO - Running <TaskInstance: pytorch_circle_classifier.wait_for_test_file scheduled__2025-10-05T00:00:00+00:00 [running]> on host ea010b5ab1b3
[2025-10-06T23:45:52.396+0000] {taskinstance.py:1509} INFO - Exporting the following env vars:
AIRFLOW_CTX_DAG_OWNER=Aditya
AIRFLOW_CTX_DAG_ID=pytorch_circle_classifier
AIRFLOW_CTX_TASK_ID=wait_for_test_file
AIRFLOW_CTX_EXECUTION_DATE=2025-10-05T00:00:00+00:00
AIRFLOW_CTX_TRY_NUMBER=1
AIRFLOW_CTX_DAG_RUN_ID=scheduled__2025-10-05T00:00:00+00:00
[2025-10-06T23:45:52.405+0000] {taskinstance.py:1768} ERROR - Task failed with exception
Traceback (most recent call last):
  File "/home/airflow/.local/lib/python3.7/site-packages/airflow/sensors/base.py", line 199, in execute
    poke_return = self.poke(context)
  File "/home/airflow/.local/lib/python3.7/site-packages/airflow/sensors/filesystem.py", line 61, in poke
    hook = FSHook(self.fs_conn_id)
  File "/home/airflow/.local/lib/python3.7/site-packages/airflow/hooks/filesystem.py", line 38, in __init__
    conn = self.get_connection(conn_id)
  File "/home/airflow/.local/lib/python3.7/site-packages/airflow/hooks/base.py", line 72, in get_connection
    conn = Connection.get_connection_from_secrets(conn_id)
  File "/home/airflow/.local/lib/python3.7/site-packages/airflow/models/connection.py", line 435, in get_connection_from_secrets
    raise AirflowNotFoundException(f"The conn_id `{conn_id}` isn't defined")
airflow.exceptions.AirflowNotFoundException: The conn_id `fs_default` isn't defined
[2025-10-06T23:45:52.408+0000] {taskinstance.py:1323} INFO - Marking task as UP_FOR_RETRY. dag_id=pytorch_circle_classifier, task_id=wait_for_test_file, execution_date=20251005T000000, start_date=20251006T234551, end_date=20251006T234552
[2025-10-06T23:45:52.416+0000] {standard_task_runner.py:105} ERROR - Failed to execute job 8 for task wait_for_test_file (The conn_id `fs_default` isn't defined; 130)
[2025-10-06T23:45:52.454+0000] {local_task_job.py:208} INFO - Task exited with return code 1
[2025-10-06T23:45:52.470+0000] {taskinstance.py:2578} INFO - 0 downstream tasks scheduled from follow-on schedule check
